<mujoco model="planar walker">
<!--  <include file="./common/visual.xml"/>-->
<!--  <include file="./common/skybox.xml"/>-->
<!--  <include file="./common/materials.xml"/>-->
  <compiler angle="radian"/>

<!--  <option timestep="0.0025"/>-->

<!--  <statistic extent="2" center="0 0 1"/>-->

  <asset>
    <material name="self" rgba=".7 .5 .3 1"/>
  </asset>

  <default>
    <joint damping=".1" armature="0.01" limited="true" solimplimit="0 .99 .01"/>
    <geom contype="1" conaffinity="0" friction=".7 .1 .1"/>
    <motor ctrlrange="-1 1" ctrllimited="true"/>
    <site size="0.01"/>
    <default class="walker">
      <geom material="self" type="capsule"/>
      <joint axis="0 -1 0"/>
    </default>
    <default class="rangefinder">
      <site type="capsule" size=".05 .5" rgba="1 0 0 .4" group="4"/>
    </default>
  </default>

  <worldbody>
<!--    <geom name="floor" type="plane" conaffinity="1" pos="248 0 0" size="250 .8 .2" zaxis="0 0 1"/>-->
    <camera name="sideon" pos="0 -3 3" euler="0.7854 0 0" mode="trackcom"/>
<!--    <camera name="sideon" pos="0 -10 5" fovy="45" mode="targetbody" target="torso" />-->
    <camera name="float_far"  pos="-4 0 2" xyaxes="0 -1 0 .5 0 1" mode="trackcom" fovy="90"/>
    <body name="torso" pos="0 0 1.3" childclass="walker">
<!--      <light name="light" pos="0 0 2" mode="trackcom"/>-->

      <camera name="floating"  pos="-2 0 1" xyaxes="0 -1 0 .5 0 1" mode="trackcom" fovy="90"/>
      <camera name="egocentric"  pos=".07 0 .2" xyaxes="0 -1 0 0 0 1" fovy="90"/>

<!--      <joint name="rootz" axis="0 0 1" type="slide" limited="false" armature="0" damping="0"/>-->
<!--      <joint name="rootx" axis="1 0 0" type="slide" limited="false" armature="0" damping="0"/>-->
<!--      <joint name="rooty" axis="0 1 0" type="hinge" limited="false" armature="0" damping="0"/>  &lt;!&ndash; can only rotate around y axis &ndash;&gt;-->

      <site name="torso_touch" type="box" size="0.08 0.08 0.31" rgba="0 0 1 1" group="4"/>
      <geom name="torso" size="0.07 0.3"/>
      <site name="torso_site" size="0.05" rgba="1 0 0 1"/>

      <site name="rf_xp" class="rangefinder" pos="0.07 0 0.2" zaxis="1 0 0"/>
      <site name="rf_xpd_30" class="rangefinder" pos="0.07 0 0.2" xyaxes="-1 0 -1.7321 0 1 0"/>  <!-- 30 degree -->
      <site name="rf_xpyp" class="rangefinder" pos="0.07 0.07 0.2" zaxis="1 1 0"/>
      <site name="rf_xpypd_30" class="rangefinder" pos="0.07 0.07 0.2" xyaxes="-1 -1 -1.7321 -1 1 0"/>
      <site name="rf_xpyn" class="rangefinder" pos="0.07 -0.07 0.2"  zaxis="1 -1 0"/>
      <site name="rf_xpynd_30" class="rangefinder" pos="0.07 -0.07 0.2" xyaxes="-1 1 -1.7321 1 1 0"/>

      <body name="right_thigh" pos="0 -.05 -0.3">
        <joint name="right_hip" range="-0.34907 1.74533"/>  <!-- range = [-20 deg, 100 deg] -->
<!--        <joint name="right_hip" range="-20 100"/>-->
        <geom name="right_thigh" pos="0 0 -0.225" size="0.05 0.225"/>
        <body name="right_leg" pos="0 0 -0.7">
          <joint name="right_knee" pos="0 0 0.25" range="-2.61799 0"/>  <!-- range = [-150 deg, 0 deg] -->
<!--          <joint name="right_knee" pos="0 0 0.25" range="-150 0"/>  &lt;!&ndash; range = [-150 deg, 0 deg] &ndash;&gt;-->
          <geom name="right_leg" size="0.04 0.25"/>
          <body name="right_foot" pos="0.06 0 -0.25">
            <joint name="right_ankle" pos="-0.06 0 0" range="-0.78540 0.78540"/>  <!-- range = [-45 deg, 45 deg] -->
<!--            <joint name="right_ankle" pos="-0.06 0 0" range="-45 45"/>-->
            <geom name="right_foot" zaxis="1 0 0" size="0.05 0.1"/>
          </body>
        </body>
      </body>
      <body name="left_thigh" pos="0 .05 -0.3" >
        <joint name="left_hip" range="-0.34907 1.74533"/>  <!-- range = [-20 deg, 100 deg] -->
<!--        <joint name="left_hip" range="-20 100"/>-->
        <geom name="left_thigh" pos="0 0 -0.225" size="0.05 0.225"/>
        <body name="left_leg" pos="0 0 -0.7">
          <joint name="left_knee" pos="0 0 0.25" range="-2.61799 0"/>  <!-- range = [-150 deg, 0 deg] -->
<!--          <joint name="left_knee" pos="0 0 0.25" range="-150 0"/>-->
          <geom name="left_leg" size="0.04 0.25"/>
          <body name="left_foot" pos="0.06 0 -0.25">
            <joint name="left_ankle" pos="-0.06 0 0" range="-0.78540 0.78540"/>  <!-- range = [-45 deg, 45 deg] -->
<!--            <joint name="left_ankle" pos="-0.06 0 0" range="-45 45"/>-->
            <geom name="left_foot" zaxis="1 0 0" size="0.05 0.1"/>
          </body>
        </body>
      </body>
    </body>
  </worldbody>

  <sensor>
    <subtreelinvel name="torso_subtreelinvel" body="torso"/>
    <touch name="torso_touch" site="torso_touch"/>
    <velocimeter name="torso_vel" site="torso_site"/>
    <gyro name="torso_gyro" site="torso_site"/>
    <accelerometer name="torso_accel" site="torso_site"/>
    <rangefinder name="rf_xp" site="rf_xp"/>
    <rangefinder name="rf_xpd_30" site="rf_xpd_30"/>
    <rangefinder name="rf_xpyp" site="rf_xpyp"/>
    <rangefinder name="rf_xpypd_30" site="rf_xpypd_30"/>
    <rangefinder name="rf_xpyn" site="rf_xpyn"/>
    <rangefinder name="rf_xpynd_30" site="rf_xpynd_30"/>
  </sensor>

  <actuator>
    <motor name="right_hip" joint="right_hip" gear="100"/>
    <motor name="right_knee" joint="right_knee" gear="50"/>
    <motor name="right_ankle" joint="right_ankle" gear="20"/>
    <motor name="left_hip" joint="left_hip" gear="100"/>
    <motor name="left_knee" joint="left_knee" gear="50"/>
    <motor name="left_ankle" joint="left_ankle" gear="20"/>
  </actuator>
</mujoco>
